Workbook

Sheet Income Statement
A1: Kraft Heinz Company (KHC) — Forecasted Income Statement
A2: $ in millions, except per-share data | Unadjusted historical financials (FactSet) | Blue = hardcoded input, Black = formula
B3: Historical | M3: Forecast
B4: 2016 | C4: 2017 | D4: 2018 | E4: 2019 | F4: 2020 | G4: 2021 | H4: 2022 | I4: 2023 | J4: 2024 | K4: 2025 | M4: 2026 | N4: 2027 | O4: 2028 | P4: 2029 | Q4: 2030
A6: Net Sales | B6: 26481 | C6: 26076 | D6: 26268 | E6: 24977 | F6: 26184 | G6: 26043 | H6: 26484 | I6: 26640 | J6: 25846 | K6: 24942 | M6: =K6*(1+$C$41) -> 24786.539 | N6: =M6*(1+$C$41) -> 24632.048 | O6: =N6*(1+$C$41) -> 24478.519 | P6: =O6*(1+$C$41) -> 24325.947 | Q6: =P6*(1+$C$41) -> 24174.326
A7: % Growth (YoY) | C7: =C6/B6-1 -> -0.015293984 | D7: =D6/C6-1 -> 0.0073630925 | E7: =E6/D6-1 -> -0.049147251 | F7: =F6/E6-1 -> 0.048324459 | G7: =G6/F6-1 -> -0.0053849679 | H7: =H6/G6-1 -> 0.016933533 | I7: =I6/H6-1 -> 0.0058903489 | J7: =J6/I6-1 -> -0.029804805 | K7: =K6/J6-1 -> -0.034976399 | M7: =M6/K6-1 -> -0.006232886 | N7: =N6/M6-1 -> -0.006232886 | O7: =O6/N6-1 -> -0.006232886 | P7: =P6/O6-1 -> -0.006232886 | Q7: =Q6/P6-1 -> -0.006232886
A9: Cost of Goods Sold, excl. D&A | B9: 14903 | C9: 15469 | D9: 16122 | E9: 15854 | F9: 16009 | G9: 16546 | H9: 17480 | I9: 16614 | J9: 15909 | K9: 15599 | M9: =M6*M10 -> 15307.8 | N9: =N6*N10 -> 15212.388 | O9: =O6*O10 -> 15117.571 | P9: =P6*P10 -> 15023.345 | Q9: =Q6*Q10 -> 14929.706
A10: COGS excl. D&A % of Net Sales | B10: =B9/B6 -> 0.56278086 | C10: =C9/C6 -> 0.59322749 | D10: =D9/D6 -> 0.61375057 | E10: =E9/E6 -> 0.63474396 | F10: =F9/F6 -> 0.61140391 | G10: =G9/G6 -> 0.63533387 | H10: =H9/H6 -> 0.66002114 | I10: =I9/I6 -> 0.62364865 | ... K10: =K9/K6 -> 0.62541095 | M10: =$C$42 -> 0.61758519 | N10: =$C$42 -> 0.61758519 | O10: =$C$42 -> 0.61758519 | P10: =$C$42 -> 0.61758519 | Q10: =$C$42 -> 0.61758519
A11: Depreciation Expense | B11: 1069 | C11: 753 | D11: 693 | E11: 708 | F11: 705 | G11: 671 | H11: 672 | I11: 710 | J11: 696 | K11: 722 | M11: =M12*'Balance Sheet'!K18 -> 753.36108 | N11: =N12*'Balance Sheet'!M18 -> 767.2763 | O11: =O12*'Balance Sheet'!N18 -> 779.31599 | P11: =P12*'Balance Sheet'!O18 -> 789.66375 | Q11: =Q12*'Balance Sheet'!P18 -> 798.48556
A12: Depreciation % of Prior-Year Net PP&E | C12: =C11/'Balance Sheet'!B18 -> 0.11258971 | D12: =D11/'Balance Sheet'!C18 -> 0.098144739 | E12: =E11/'Balance Sheet'!D18 -> 0.10002826 | F12: =F11/'Balance Sheet'!E18 -> 0.092799789 | G12: =G11/'Balance Sheet'!F18 -> 0.090212423 | H12: =H11/'Balance Sheet'!G18 -> 0.091118644 | I12: =I11/'Balance Sheet'!H18 -> 0.095842333 | J12: =J11/'Balance Sheet'!I18 -> 0.09043659 | K12: =K11/'Balance Sheet'!J18 -> 0.093875959 | M12: =$C$43 -> 0.096116494 | N12: =$C$43 -> 0.096116494 | O12: =$C$43 -> 0.096116494 | P12: =$C$43 -> 0.096116494 | Q12: =$C$43 -> 0.096116494
A13: Amortization Expense | B13: 268 | C13: 278 | D13: 290 | E13: 286 | F13: 264 | G13: 239 | H13: 261 | I13: 251 | J13: 252 | K13: 246 | M13: =M14*'Balance Sheet'!K21 -> 207.86039 | N13: =N14*'Balance Sheet'!M21 -> 206.70912 | O13: =O14*'Balance Sheet'!N21 -> 205.56423 | P13: =P14*'Balance Sheet'!O21 -> 204.42568 | Q13: =Q14*'Balance Sheet'!P21 -> 203.29343
A14: Amortization % of Prior-Year Intangible Assets | C14: =C13/'Balance Sheet'!B21 -> 0.0046882642 | D14: =D13/'Balance Sheet'!C21 -> 0.0048795262 | E14: =E13/'Balance Sheet'!D21 -> 0.0057815153 | F14: =F13/'Balance Sheet'!E21 -> 0.0054262929 | G14: =G13/'Balance Sheet'!F21 -> 0.005121392 | H14: =H13/'Balance Sheet'!G21 -> 0.0059942125 | I14: =I13/'Balance Sheet'!H21 -> 0.0058852494 | J14: =J13/'Balance Sheet'!I21 -> 0.0059366755 | K14: =K13/'Balance Sheet'!J21 -> 0.0061348163 | M14: =$C$44 -> 0.0055386605 | N14: =$C$44 -> 0.0055386605 | O14: =$C$44 -> 0.0055386605 | P14: =$C$44 -> 0.0055386605 | Q14: =$C$44 -> 0.0055386605
A15: Cost of Goods Sold, incl. D&A | B15: =B9+B11+B13 -> 16240 | C15: =C9+C11+C13 -> 16500 | D15: =D9+D11+D13 -> 17105 | E15: =E9+E11+E13 -> 16848 | F15: =F9+F11+F13 -> 16978 | G15: =G9+G11+G13 -> 17456 | H15: =H9+H11+H13 -> 18413 | I15: =I9+I11+I13 -> 17575 | ... K15: =K9+K11+K13 -> 16567 | M15: =M9+M11+M13 -> 16269.021 | N15: =N9+N11+N13 -> 16186.373 | O15: =O9+O11+O13 -> 16102.451 | P15: =P9+P11+P13 -> 16017.434 | Q15: =Q9+Q11+Q13 -> 15931.485
A16: Gross Profit | B16: =B6-B15 -> 10241 | C16: =C6-C15 -> 9576 | D16: =D6-D15 -> 9163 | E16: =E6-E15 -> 8129 | F16: =F6-F15 -> 9206 | G16: =G6-G15 -> 8587 | H16: =H6-H15 -> 8071 | I16: =I6-I15 -> 9065 | ... K16: =K6-K15 -> 8375 | M16: =M6-M15 -> 8517.5184 | N16: =N6-N15 -> 8445.6745 | O16: =O6-O15 -> 8376.068 | P16: =P6-P15 -> 8308.5131 | Q16: =Q6-Q15 -> 8242.8415
A18: SG&A Expense | B18: 3143 | C18: 2601 | D18: 3305 | E18: 3124 | F18: 3615 | G18: 3517 | H18: 3530 | I18: 3689 | J18: 3597 | K18: 3660 | M18: =M6*M19 -> 3222.5265 | N18: =N6*N19 -> 3202.4409 | O18: =O6*O19 -> 3182.4805 | P18: =P6*P19 -> 3162.6444 | Q18: =Q6*Q19 -> 3142.932
A19: SG&A % of Net Sales | B19: =B18/B6 -> 0.11868887 | C19: =C18/C6 -> 0.099746894 | D19: =D18/D6 -> 0.12581849 | E19: =E18/E6 -> 0.12507507 | F19: =F18/F6 -> 0.13806141 | G19: =G18/G6 -> 0.13504589 | H19: =H18/H6 -> 0.13328802 | I19: =I18/I6 -> 0.13847598 | ... K19: =K18/K6 -> 0.14674044 | M19: =$C$45 -> 0.13001115 | N19: =$C$45 -> 0.13001115 | O19: =$C$45 -> 0.13001115 | P19: =$C$45 -> 0.13001115 | Q19: =$C$45 -> 0.13001115
A20: EBIT (Operating Income) | B20: =B16-B18 -> 7098 | C20: =C16-C18 -> 6975 | D20: =D16-D18 -> 5858 | E20: =E16-E18 -> 5005 | F20: =F16-F18 -> 5591 | G20: =G16-G18 -> 5070 | H20: =H16-H18 -> 4541 | I20: =I16-I18 -> 5376 | ... K20: =K16-K18 -> 4715 | M20: =M16-M18 -> 5294.9918 | N20: =N16-N18 -> 5243.2336 | O20: =O16-O18 -> 5193.5876 | P20: =P16-P18 -> 5145.8687 | Q20: =Q16-Q18 -> 5099.9095
A22: Nonoperating Income - Net | B22: 67 | C22: 264 | D22: 495 | E22: 1049 | F22: 240 | G22: 418 | H22: 340 | I22: 64 | J22: 85 | K22: 209 | M22: =$K$22 -> 209 | N22: =$K$22 -> 209 | O22: =$K$22 -> 209 | P22: =$K$22 -> 209 | Q22: =$K$22 -> 209
A23: Unusual Expense - Net | B23: 1012 | C23: 483 | D23: 16396 | E23: 2007 | F23: 3397 | G23: 1718 | H23: 987 | I23: 887 | J23: 3689 | K23: 9395 | M23: 0 | N23: 0 | O23: 0 | P23: 0 | Q23: 0
A24: Interest Expense | B24: 1130 | C24: 1306 | D24: 1278 | E24: 1386 | F24: 1404 | G24: 2062 | H24: 928 | I24: 920 | J24: 932 | K24: 974 | M24: =M25*('Balance Sheet'!K31+'Balance Sheet'!K36) -> 1021.1056 | N24: =N25*('Balance Sheet'!M31+'Balance Sheet'!M36) -> 1021.1056 | O24: =O25*('Balance Sheet'!N31+'Balance Sheet'!N36) -> 1021.1056 | P24: =P25*('Balance Sheet'!O31+'Balance Sheet'!O36) -> 1021.1056 | Q24: =Q25*('Balance Sheet'!P31+'Balance Sheet'!P36) -> 1021.1056
A25: Interest Expense % of Prior-Year Total Debt | C25: =C24/('Balance Sheet'!B31+'Balance Sheet'!B36) -> 0.040303666 | D25: =D24/('Balance Sheet'!C31+'Balance Sheet'!C36) -> 0.040567565 | E25: =E24/('Balance Sheet'!D31+'Balance Sheet'!D36) -> 0.044468686 | F25: =F24/('Balance Sheet'!E31+'Balance Sheet'!E36) -> 0.047043056 | G25: =G24/('Balance Sheet'!F31+'Balance Sheet'!F36) -> 0.071310001 | H25: =H24/('Balance Sheet'!G31+'Balance Sheet'!G36) -> 0.041369472 | I25: =I24/('Balance Sheet'!H31+'Balance Sheet'!H36) -> 0.04427334 | J25: =J24/('Balance Sheet'!I31+'Balance Sheet'!I36) -> 0.045135358 | K25: =K24/('Balance Sheet'!J31+'Balance Sheet'!J36) -> 0.047628362 | M25: =$C$46 -> 0.046899945 | N25: =$C$46 -> 0.046899945 | O25: =$C$46 -> 0.046899945 | P25: =$C$46 -> 0.046899945 | Q25: =$C$46 -> 0.046899945
A26: Pretax Income | B26: =B20+B22-B23-B24 -> 5023 | C26: =C20+C22-C23-C24 -> 5450 | D26: =D20+D22-D23-D24 -> -11321 | E26: =E20+E22-E23-E24 -> 2661 | F26: =F20+F22-F23-F24 -> 1030 | G26: =G20+G22-G23-G24 -> 1708 | H26: =H20+H22-H23-H24 -> 2966 | I26: =I20+I22-I23-I24 -> 3633 | ... K26: =K20+K22-K23-K24 -> -5445 | M26: =M20+M22-M23-M24 -> 4482.8862 | N26: =N20+N22-N23-N24 -> 4431.128 | O26: =O20+O22-O23-O24 -> 4381.482 | P26: =P20+P22-P23-P24 -> 4333.7631 | Q26: =Q20+Q22-Q23-Q24 -> 4287.8039
A27: Income Taxes | B27: 1381 | C27: -5482 | D27: -1067 | E27: 728 | F27: 669 | G27: 684 | H27: 598 | I27: 787 | J27: -1890 | K27: 403 | M27: =M26*M28 -> 1084.8585 | N27: =N26*N28 -> 1072.333 | O27: =O26*O28 -> 1060.3186 | P27: =P26*P28 -> 1048.7707 | Q27: =Q26*Q28 -> 1037.6485
A28: Effective Tax Rate | B28: =B27/B26 -> 0.2749353 | C28: =C27/C26 -> -1.0058716 | D28: =D27/D26 -> 0.094249625 | E28: =E27/E26 -> 0.27358136 | F28: =F27/F26 -> 0.64951456 | G28: =G27/G26 -> 0.40046838 | H28: =H27/H26 -> 0.20161834 | I28: =I27/I26 -> 0.21662538 | ... K28: =K27/K26 -> -0.074012856 | M28: =$C$48 -> 0.242 | N28: =$C$48 -> 0.242 | O28: =$C$48 -> 0.242 | P28: =$C$48 -> 0.242 | Q28: =$C$48 -> 0.242
A29: Consolidated Net Income | B29: =B26-B27 -> 3642 | C29: =C26-C27 -> 10932 | D29: =D26-D27 -> -10254 | E29: =E26-E27 -> 1933 | F29: =F26-F27 -> 361 | G29: =G26-G27 -> 1024 | H29: =H26-H27 -> 2368 | I29: =I26-I27 -> 2846 | ... K29: =K26-K27 -> -5848 | M29: =M26-M27 -> 3398.0277 | N29: =N26-N27 -> 3358.795 | O29: =O26-O27 -> 3321.1633 | P29: =P26-P27 -> 3284.9924 | Q29: =Q26-Q27 -> 3250.1553
A30: Minority Interest | B30: 10 | C30: -9 | D30: -62 | E30: -2 | F30: 5 | G30: 12 | H30: 5 | I30: -9 | J30: 2 | K30: -2 | M30: =$K$30 -> -2 | N30: =$K$30 -> -2 | O30: =$K$30 -> -2 | P30: =$K$30 -> -2 | Q30: =$K$30 -> -2
A31: Net Income | B31: =B29-B30 -> 3632 | C31: =C29-C30 -> 10941 | D31: =D29-D30 -> -10192 | E31: =E29-E30 -> 1935 | F31: =F29-F30 -> 356 | G31: =G29-G30 -> 1012 | H31: =H29-H30 -> 2363 | I31: =I29-I30 -> 2855 | ... K31: =K29-K30 -> -5846 | M31: =M29-M30 -> 3400.0277 | N31: =N29-N30 -> 3360.795 | O31: =O29-O30 -> 3323.1633 | P31: =P29-P30 -> 3286.9924 | Q31: =Q29-Q30 -> 3252.1553
A32: Preferred Dividends | B32: 180 | C32: 0 | D32: 0 | E32: 0 | F32: 0 | G32: 0 | H32: 0 | I32: 0 | J32: 0 | K32: 0 | M32: =$K$32 -> 0 | N32: =$K$32 -> 0 | O32: =$K$32 -> 0 | P32: =$K$32 -> 0 | Q32: =$K$32 -> 0
A33: Net Income Available to Common | B33: =B31-B32 -> 3452 | C33: =C31-C32 -> 10941 | D33: =D31-D32 -> -10192 | E33: =E31-E32 -> 1935 | F33: =F31-F32 -> 356 | G33: =G31-G32 -> 1012 | H33: =H31-H32 -> 2363 | I33: =I31-I32 -> 2855 | ... K33: =K31-K32 -> -5846 | M33: =M31-M32 -> 3400.0277 | N33: =N31-N32 -> 3360.795 | O33: =O31-O32 -> 3323.1633 | P33: =P31-P32 -> 3286.9924 | Q33: =Q31-Q32 -> 3252.1553
A35: Memo: Basic Shares Outstanding | B35: 1217 | C35: 1218 | D35: 1219 | E35: 1221 | F35: 1223 | G35: 1224 | H35: 1226 | I35: 1227 | J35: 1210 | K35: 1187 | M35: =$K$35 -> 1187 | N35: =$K$35 -> 1187 | O35: =$K$35 -> 1187 | P35: =$K$35 -> 1187 | Q35: =$K$35 -> 1187
A36: Memo: Dividends per Share (historical) | B36: 2.35 | C36: 2.45 | D36: 2.5 | E36: 1.6 | F36: 1.6 | G36: 1.6 | H36: 1.6 | I36: 1.6 | J36: 1.6 | K36: 1.6
A38: KEY ASSUMPTIONS (drive the forecast)
A39: Historical Average Revenue Growth Rate | C39: =AVERAGE(C7:K7) -> -0.006232886
A40: Sustainable Growth Rate, FY25 (ROE x Retention) — reference only | C40: =(K33/'Balance Sheet'!J50)*(1-('Balance Sheet'!K56/K33)) -> -0.15699949
A41: Selected Revenue Growth Rate (used in forecast) | C41: =C39 -> -0.006232886
A42: Average COGS excl. D&A % of Net Sales | C42: =AVERAGE(B10:K10) -> 0.61758519
A43: Average Depreciation % of Prior-Year Net PP&E | C43: =AVERAGE(C12:K12) -> 0.096116494
A44: Average Amortization % of Prior-Year Intangible Assets | C44: =AVERAGE(C14:K14) -> 0.0055386605
A45: Average SG&A % of Net Sales | C45: =AVERAGE(B19:K19) -> 0.13001115
A46: Average Interest Expense % of Prior-Year Total Debt | C46: =AVERAGE(C25:K25) -> 0.046899945
...

Sheet Balance Sheet
A1: Kraft Heinz Company (KHC) — Forecasted Balance Sheet
A2: $ in millions | Unadjusted historical financials (FactSet) | Blue = hardcoded input, Black = formula, Green = link to other sheet
B3: Historical | M3: Forecast
B4: 2016 | C4: 2017 | D4: 2018 | E4: 2019 | F4: 2020 | G4: 2021 | H4: 2022 | I4: 2023 | J4: 2024 | K4: 2025 | M4: 2026 | N4: 2027 | O4: 2028 | P4: 2029 | Q4: 2030
A6: ASSETS
A7: Cash & Short-Term Investments | B7: 4204 | C7: 1769 | D7: 1131 | E7: 2280 | F7: 3417 | G7: 3445 | H7: 1040 | I7: 1403 | J7: 1365 | K7: 3839 | M7: =M52-(M8+M10+M12+M18+M22+M24) -> 5396.0447 | N7: =N52-(N8+N10+N12+N18+N22+N24) -> 6344.5677 | O7: =O52-(O8+O10+O12+O18+O22+O24) -> 7299.668 | P7: =P52-(P8+P10+P12+P18+P22+P24) -> 8260.0192 | Q7: =Q52-(Q8+Q10+Q12+Q18+Q22+Q24) -> 9224.4268
A8: Accounts Receivable, Net | B8: 898 | C8: 1274 | D8: 2129 | E8: 1973 | F8: 2063 | G8: 1957 | H8: 2120 | I8: 2112 | J8: 2147 | K8: 2254 | M8: ='Income Statement'!M6/M9 -> 1661.6969 | N8: ='Income Statement'!N6/N9 -> 1651.3397 | O8: ='Income Statement'!O6/O9 -> 1641.0471 | P8: ='Income Statement'!P6/P9 -> 1630.8186 | Q8: ='Income Statement'!Q6/Q9 -> 1620.6539
A9: AR Turnover (Net Sales / AR) | B9: ='Income Statement'!B6/B8 -> 29.488864 | C9: ='Income Statement'!C6/C8 -> 20.467818 | D9: ='Income Statement'!D6/D8 -> 12.338187 | E9: ='Income Statement'!E6/E8 -> 12.659402 | F9: ='Income Statement'!F6/F8 -> 12.692196 | G9: ='Income Statement'!G6/G8 -> 13.307614 | H9: ='Income Statement'!H6/H8 -> 12.492453 | I9: ='Income Statement'!I6/I8 -> 12.613636 | ... K9: ='Income Statement'!K6/K8 -> 11.065661 | M9: =$C$60 -> 14.916402 | N9: =$C$60 -> 14.916402 | O9: =$C$60 -> 14.916402 | P9: =$C$60 -> 14.916402 | Q9: =$C$60 -> 14.916402
A10: Inventories | B10: 2684 | C10: 2760 | D10: 2667 | E10: 2721 | F10: 2554 | G10: 2729 | H10: 3651 | I10: 3614 | J10: 3376 | K10: 3167 | M10: ='Income Statement'!M15/M11 -> 2814.2679 | N10: ='Income Statement'!N15/N11 -> 2799.9713 | O10: ='Income Statement'!O15/O11 -> 2785.4541 | P10: ='Income Statement'!P15/P11 -> 2770.7476 | Q10: ='Income Statement'!Q15/Q11 -> 2755.8798
A11: Inventory Turnover (COGS incl. D&A / Inventory) | B11: ='Income Statement'!B15/B10 -> 6.0506706 | C11: ='Income Statement'!C15/C10 -> 5.9782609 | D11: ='Income Statement'!D15/D10 -> 6.4135733 | E11: ='Income Statement'!E15/E10 -> 6.1918412 | F11: ='Income Statement'!F15/F10 -> 6.6476116 | G11: ='Income Statement'!G15/G10 -> 6.3964822 | H11: ='Income Statement'!H15/H10 -> 5.0432758 | I11: ='Income Statement'!I15/I10 -> 4.8630327 | ... K11: ='Income Statement'!K15/K10 -> 5.2311336 | M11: =$C$61 -> 5.7809069 | N11: =$C$61 -> 5.7809069 | O11: =$C$61 -> 5.7809069 | P11: =$C$61 -> 5.7809069 | Q11: =$C$61 -> 5.7809069
A12: Other Current Assets | B12: 967 | C12: 1398 | D12: 3148 | E12: 1123 | F12: 2788 | G12: 863 | H12: 1086 | I12: 800 | J12: 767 | K12: 867 | M12: ='Income Statement'!M6*M13 -> 1313.7345 | N12: ='Income Statement'!N6*N13 -> 1305.5462 | O12: ='Income Statement'!O6*O13 -> 1297.4088 | P12: ='Income Statement'!P6*P13 -> 1289.3222 | Q12: ='Income Statement'!Q6*Q13 -> 1281.286
A13: Other Current Assets % of Net Sales | B13: =B12/'Income Statement'!B6 -> 0.036516748 | C13: =C12/'Income Statement'!C6 -> 0.053612517 | D13: =D12/'Income Statement'!D6 -> 0.11984163 | E13: =E12/'Income Statement'!E6 -> 0.044961364 | F13: =F12/'Income Statement'!F6 -> 0.10647724 | G13: =G12/'Income Statement'!G6 -> 0.033137503 | H13: =H12/'Income Statement'!H6 -> 0.04100589 | I13: =I12/'Income Statement'!I6 -> 0.03003003 | ... K13: =K12/'Income Statement'!K6 -> 0.034760645 | M13: =$C$64 -> 0.053001934 | N13: =$C$64 -> 0.053001934 | O13: =$C$64 -> 0.053001934 | P13: =$C$64 -> 0.053001934 | Q13: =$C$64 -> 0.053001934
A14: Total Current Assets | B14: =B7+B8+B10+B12 -> 8753 | C14: =C7+C8+C10+C12 -> 7201 | D14: =D7+D8+D10+D12 -> 9075 | E14: =E7+E8+E10+E12 -> 8097 | F14: =F7+F8+F10+F12 -> 10822 | G14: =G7+G8+G10+G12 -> 8994 | H14: =H7+H8+H10+H12 -> 7897 | I14: =I7+I8+I10+I12 -> 7929 | ... K14: =K7+K8+K10+K12 -> 10127 | M14: =M7+M8+M10+M12 -> 11185.744 | N14: =N7+N8+N10+N12 -> 12101.425 | O14: =O7+O8+O10+O12 -> 13023.578 | P14: =P7+P8+P10+P12 -> 13950.908 | Q14: =Q7+Q8+Q10+Q12 -> 14882.247
A16: Capital Expenditures (historical actual / forecast via ratio) | B16: 1247 | C16: 1194 | D16: 826 | E16: 768 | F16: 596 | G16: 905 | H16: 916 | I16: 1013 | J16: 1164 | K16: 801 | M16: ='Income Statement'!M6*M17 -> 898.13564 | N16: ='Income Statement'!N6*N17 -> 892.53766 | O16: ='Income Statement'!O6*O17 -> 886.97457 | P16: ='Income Statement'!P6*P17 -> 881.44616 | Q16: ='Income Statement'!Q6*Q17 -> 875.95221
A17: CapEx % of Net Sales | B17: =B16/'Income Statement'!B6 -> 0.047090367 | C17: =C16/'Income Statement'!C6 -> 0.045789231 | D17: =D16/'Income Statement'!D6 -> 0.031445104 | E17: =E16/'Income Statement'!E6 -> 0.030748288 | F17: =F16/'Income Statement'!F6 -> 0.022761992 | G17: =G16/'Income Statement'!G6 -> 0.034750221 | H17: =H16/'Income Statement'!H6 -> 0.03458692 | I17: =I16/'Income Statement'!I6 -> 0.038025526 | ... K17: =K16/'Income Statement'!K6 -> 0.032114506 | M17: =$C$63 -> 0.036234814 | N17: =$C$63 -> 0.036234814 | O17: =$C$63 -> 0.036234814 | P17: =$C$63 -> 0.036234814 | Q17: =$C$63 -> 0.036234814
A18: Net Property, Plant & Equipment | B18: 6688 | C18: 7061 | D18: 7078 | E18: 7597 | F18: 7438 | G18: 7375 | H18: 7408 | I18: 7696 | J18: 7691 | K18: 7838 | M18: =K18+M16-'Income Statement'!M11 -> 7982.7746 | N18: =M18+N16-'Income Statement'!N11 -> 8108.0359 | O18: =N18+O16-'Income Statement'!O11 -> 8215.6945 | P18: =O18+P16-'Income Statement'!P11 -> 8307.4769 | Q18: =P18+Q16-'Income Statement'!Q11 -> 8384.9436
A20: Goodwill | B20: 44125 | C20: 44825 | D20: 36503 | E20: 35546 | F20: 33089 | G20: 31296 | H20: 30833 | I20: 30459 | J20: 28673 | K20: 22179 | M20: =$K$20 -> 22179 | N20: =$K$20 -> 22179 | O20: =$K$20 -> 22179 | P20: =$K$20 -> 22179 | Q20: =$K$20 -> 22179
A21: Other Intangible Assets (amortizable) | B21: 59297 | C21: 59432 | D21: 49468 | E21: 48652 | F21: 46667 | G21: 43542 | H21: 42649 | I21: 42448 | J21: 40099 | K21: 37529 | M21: =K21-'Income Statement'!M13 -> 37321.14 | N21: =M21-'Income Statement'!N13 -> 37114.43 | O21: =N21-'Income Statement'!O13 -> 36908.866 | P21: =O21-'Income Statement'!P13 -> 36704.441 | Q21: =P21-'Income Statement'!Q13 -> 36501.147
A22: Total Intangible Assets | B22: =B20+B21 -> 103422 | C22: =C20+C21 -> 104257 | D22: =D20+D21 -> 85971 | E22: =E20+E21 -> 84198 | F22: =F20+F21 -> 79756 | G22: =G20+G21 -> 74838 | H22: =H20+H21 -> 73482 | I22: =I20+I21 -> 72907 | ... K22: =K20+K21 -> 59708 | M22: =M20+M21 -> 59500.14 | N22: =N20+N21 -> 59293.43 | O22: =O20+O21 -> 59087.866 | P22: =P20+P21 -> 58883.441 | Q22: =Q20+Q21 -> 58680.147
A24: Other Long-Term Assets (LT Investments + Other Assets) | B24: 1617 | C24: 1573 | D24: 1337 | E24: 1558 | F24: 1814 | G24: 2187 | H24: 1726 | I24: 1807 | J24: 4169 | K24: 4113 | M24: =$K$24 -> 4113 | N24: =$K$24 -> 4113 | O24: =$K$24 -> 4113 | P24: =$K$24 -> 4113 | Q24: =$K$24 -> 4113
A26: TOTAL ASSETS | B26: =B14+B18+B22+B24 -> 120480 | C26: =C14+C18+C22+C24 -> 120092 | D26: =D14+D18+D22+D24 -> 103461 | E26: =E14+E18+E22+E24 -> 101450 | F26: =F14+F18+F22+F24 -> 99830 | G26: =G14+G18+G22+G24 -> 93394 | H26: =H14+H18+H22+H24 -> 90513 | I26: =I14+I18+I22+I24 -> 90339 | ... K26: =K14+K18+K22+K24 -> 81786 | M26: =M14+M18+M22+M24 -> 82781.658 | N26: =N14+N18+N22+N24 -> 83615.891 | O26: =O14+O18+O22+O24 -> 84440.139 | P26: =P14+P18+P22+P24 -> 85254.825 | Q26: =Q14+Q18+Q22+Q24 -> 86060.337
A28: LIABILITIES
A29: Accounts Payable | B29: 3996 | C29: 4362 | D29: 4153 | E29: 4003 | F29: 4304 | G29: 4753 | H29: 4848 | I29: 4627 | J29: 4188 | K29: 4308 | M29: ='Income Statement'!M15/M30 -> 4144.0505 | N29: ='Income Statement'!N15/N30 -> 4122.9984 | O29: ='Income Statement'!O15/O30 -> 4101.6217 | P29: ='Income Statement'!P15/P30 -> 4079.9662 | Q29: ='Income Statement'!Q15/Q30 -> 4058.0732
A30: AP Turnover (COGS incl. D&A / AP) | B30: ='Income Statement'!B15/B29 -> 4.0640641 | C30: ='Income Statement'!C15/C29 -> 3.7826685 | D30: ='Income Statement'!D15/D29 -> 4.1187094 | E30: ='Income Statement'!E15/E29 -> 4.2088434 | F30: ='Income Statement'!F15/F29 -> 3.9447026 | G30: ='Income Statement'!G15/G29 -> 3.6726278 | H30: ='Income Statement'!H15/H29 -> 3.7980611 | I30: ='Income Statement'!I15/I29 -> 3.7983575 | ... K30: ='Income Statement'!K15/K29 -> 3.845636 | M30: =$C$62 -> 3.9258742 | N30: =$C$62 -> 3.9258742 | O30: =$C$62 -> 3.9258742 | P30: =$C$62 -> 3.9258742 | Q30: =$C$62 -> 3.9258742
A31: ST Debt & Current Portion of LT Debt | B31: 2691 | C31: 3195 | D31: 398 | E31: 1175 | F31: 371 | G31: 887 | H31: 962 | I31: 754 | J31: 771 | K31: 2034 | M31: =$K$31 -> 2034 | N31: =$K$31 -> 2034 | O31: =$K$31 -> 2034 | P31: =$K$31 -> 2034 | Q31: =$K$31 -> 2034
A32: Other Current Liabilities | B32: 2814 | C32: 2597 | D32: 2952 | E32: 2697 | F32: 3386 | G32: 3424 | H32: 3218 | I32: 2656 | J32: 2294 | K32: 2436 | M32: ='Income Statement'!M6*M33 -> 2713.2297 | N32: ='Income Statement'!N6*N33 -> 2696.3184 | O32: ='Income Statement'!O6*O33 -> 2679.5126 | P32: ='Income Statement'!P6*P33 -> 2662.8115 | Q32: ='Income Statement'!Q6*Q33 -> 2646.2145
A33: Other Current Liabilities % of Net Sales | B33: =B32/'Income Statement'!B6 -> 0.10626487 | C33: =C32/'Income Statement'!C6 -> 0.099593496 | D33: =D32/'Income Statement'!D6 -> 0.11238008 | E33: =E32/'Income Statement'!E6 -> 0.10797934 | F33: =F32/'Income Statement'!F6 -> 0.12931561 | G33: =G32/'Income Statement'!G6 -> 0.13147487 | H33: =H32/'Income Statement'!H6 -> 0.12150733 | I33: =I32/'Income Statement'!I6 -> 0.0996997 | ... K33: =K32/'Income Statement'!K6 -> 0.097666586 | M33: =$C$65 -> 0.10946384 | N33: =$C$65 -> 0.10946384 | O33: =$C$65 -> 0.10946384 | P33: =$C$65 -> 0.10946384 | Q33: =$C$65 -> 0.10946384
A34: Total Current Liabilities | B34: =B29+B31+B32 -> 9501 | C34: =C29+C31+C32 -> 10154 | D34: =D29+D31+D32 -> 7503 | E34: =E29+E31+E32 -> 7875 | F34: =F29+F31+F32 -> 8061 | G34: =G29+G31+G32 -> 9064 | H34: =H29+H31+H32 -> 9028 | I34: =I29+I31+I32 -> 8037 | ... K34: =K29+K31+K32 -> 8778 | M34: =M29+M31+M32 -> 8891.2802 | N34: =N29+N31+N32 -> 8853.3169 | O34: =O29+O31+O32 -> 8815.1343 | P34: =P29+P31+P32 -> 8776.7777 | Q34: =Q29+Q31+Q32 -> 8738.2877
A36: Long-Term Debt | B36: 29713 | C36: 28308 | D36: 30770 | E36: 28670 | F36: 28545 | G36: 21545 | H36: 19818 | I36: 19895 | J36: 19679 | K36: 19738 | M36: =$K$36 -> 19738 | N36: =$K$36 -> 19738 | O36: =$K$36 -> 19738 | P36: =$K$36 -> 19738 | Q36: =$K$36 -> 19738
A37: Deferred Tax Liabilities | B37: 20848 | C37: 14039 | D37: 12202 | E37: 11878 | F37: 11462 | G37: 10536 | H37: 10152 | I37: 10201 | J37: 9679 | K37: 9022 | M37: =$K$37 -> 9022 | N37: =$K$37 -> 9022 | O37: =$K$37 -> 9022 | P37: =$K$37 -> 9022 | Q37: =$K$37 -> 9022
A38: Other LT Liabilities (Other Liab. + Provisions) | B38: 2844 | C38: 1515 | D38: 1208 | E38: 1278 | F38: 1519 | G38: 2797 | H38: 2645 | I38: 2484 | J38: 2351 | K38: 2459 | M38: =$K$38 -> 2459 | N38: =$K$38 -> 2459 | O38: =$K$38 -> 2459 | P38: =$K$38 -> 2459 | Q38: =$K$38 -> 2459
A39: TOTAL LIABILITIES | B39: =B34+B36+B37+B38 -> 62906 | C39: =C34+C36+C37+C38 -> 54016 | D39: =D34+D36+D37+D38 -> 51683 | E39: =E34+E36+E37+E38 -> 49701 | F39: =F34+F36+F37+F38 -> 49587 | G39: =G34+G36+G37+G38 -> 43942 | H39: =H34+H36+H37+H38 -> 41643 | I39: =I34+I36+I37+I38 -> 40617 | ... K39: =K34+K36+K37+K38 -> 39997 | M39: =M34+M36+M37+M38 -> 40110.28 | N39: =N34+N36+N37+N38 -> 40072.317 | O39: =O34+O36+O37+O38 -> 40034.134 | P39: =P34+P36+P37+P38 -> 39995.778 | Q39: =Q34+Q36+Q37+Q38 -> 39957.288
A41: SHAREHOLDERS' EQUITY
A42: Common Stock, Par Value | B42: 12 | C42: 12 | D42: 12 | E42: 12 | F42: 12 | G42: 12 | H42: 12 | I42: 12 | J42: 12 | K42: 12 | M42: =$K$42 -> 12 | N42: =$K$42 -> 12 | O42: =$K$42 -> 12 | P42: =$K$42 -> 12 | Q42: =$K$42 -> 12
A43: Additional Paid-In Capital | B43: 58593 | C43: 58634 | D43: 58723 | E43: 56828 | F43: 55096 | G43: 53379 | H43: 51834 | I43: 52037 | J43: 52135 | K43: 51287 | M43: =$K$43 -> 51287 | N43: =$K$43 -> 51287 | O43: =$K$43 -> 51287 | P43: =$K$43 -> 51287 | Q43: =$K$43 -> 51287
A44: Retained Earnings | B44: 588 | C44: 8495 | D44: -4853 | E44: -3060 | F44: -2694 | G44: -1682 | H44: 489 | I44: 1367 | J44: 2171 | K44: -4629 | M44: =K44+'Income Statement'!M33-M56 -> -3746.6219 | N44: =M44+'Income Statement'!N33-N56 -> -2874.4256 | O44: =N44+'Income Statement'!O33-O56 -> -2011.9955 | P44: =O44+'Income Statement'!P33-P56 -> -1158.9524 | Q44: =P44+'Income Statement'!Q33-Q56 -> -314.95037
A45: Cumulative Translation Adjustment | B45: -2412 | C45: -1587 | D45: -2476 | E45: -2230 | F45: -2218 | G45: -2285 | H45: -2845 | I45: -2634 | J45: -2999 | K45: -2301 | M45: =$K$45 -> -2301 | N45: =$K$45 -> -2301 | O45: =$K$45 -> -2301 | P45: =$K$45 -> -2301 | Q45: =$K$45 -> -2301
A46: Other Appropriated Reserves | B46: 784 | C46: 533 | D46: 533 | E46: 344 | F46: 251 | G46: 461 | H46: 35 | I46: 30 | J46: 84 | K46: -69 | M46: =$K$46 -> -69 | N46: =$K$46 -> -69 | O46: =$K$46 -> -69 | P46: =$K$46 -> -69 | Q46: =$K$46 -> -69
A47: Treasury Stock | B47: -207 | C47: -224 | D47: -282 | E47: -271 | F47: -344 | G47: -587 | H47: -847 | I47: -1286 | J47: -2218 | K47: -2636 | M47: =$K$47 -> -2636 | N47: =$K$47 -> -2636 | O47: =$K$47 -> -2636 | P47: =$K$47 -> -2636 | Q47: =$K$47 -> -2636
A48: Total Shareholders' Equity | B48: =B42+B43+B44+B45+B46+B47 -> 57358 | C48: =C42+C43+C44+C45+C46+C47 -> 65863 | D48: =D42+D43+D44+D45+D46+D47 -> 51657 | E48: =E42+E43+E44+E45+E46+E47 -> 51623 | F48: =F42+F43+F44+F45+F46+F47 -> 50103 | G48: =G42+G43+G44+G45+G46+G47 -> 49298 | H48: =H42+H43+H44+H45+H46+H47 -> 48678 | I48: =I42+I43+I44+I45+I46+I47 -> 49526 | ... K48: =K42+K43+K44+K45+K46+K47 -> 41664 | M48: =M42+M43+M44+M45+M46+M47 -> 42546.378 | N48: =N42+N43+N44+N45+N46+N47 -> 43418.574 | O48: =O42+O43+O44+O45+O46+O47 -> 44281.005 | P48: =P42+P43+P44+P45+P46+P47 -> 45134.048 | Q48: =Q42+Q43+Q44+Q45+Q46+Q47 -> 45978.05
...

Sheet Ratios
A1: Kraft Heinz Company (KHC) — Profitability, Productivity & Credit Risk Ratios (Point 3)
A2: $ in millions unless noted | Black = same-sheet formula, Green = link to other sheet
A4: Fiscal Year | B4: ='Income Statement'!B4 -> 2016 | C4: ='Income Statement'!C4 -> 2017 | D4: ='Income Statement'!D4 -> 2018 | E4: ='Income Statement'!E4 -> 2019 | F4: ='Income Statement'!F4 -> 2020 | G4: ='Income Statement'!G4 -> 2021 | H4: ='Income Statement'!H4 -> 2022 | I4: ='Income Statement'!I4 -> 2023 | ... K4: ='Income Statement'!K4 -> 2025
A6: 1. PROFITABILITY
A8: Gross Margin = Gross Profit / Net Sales | B8: ='Income Statement'!B16/'Income Statement'!B6 -> 0.38673011 | C8: ='Income Statement'!C16/'Income Statement'!C6 -> 0.36723424 | D8: ='Income Statement'!D16/'Income Statement'!D6 -> 0.34882747 | E8: ='Income Statement'!E16/'Income Statement'!E6 -> 0.32545942 | F8: ='Income Statement'!F16/'Income Statement'!F6 -> 0.35158876 | G8: ='Income Statement'!G16/'Income Statement'!G6 -> 0.32972392 | H8: ='Income Statement'!H16/'Income Statement'!H6 -> 0.30475004 | I8: ='Income Statement'!I16/'Income Statement'!I6 -> 0.34027778 | ... K8: ='Income Statement'!K16/'Income Statement'!K6 -> 0.33577901
A9: Operating Margin = EBIT / Net Sales | B9: ='Income Statement'!B20/'Income Statement'!B6 -> 0.26804124 | C9: ='Income Statement'!C20/'Income Statement'!C6 -> 0.26748734 | D9: ='Income Statement'!D20/'Income Statement'!D6 -> 0.22300898 | E9: ='Income Statement'!E20/'Income Statement'!E6 -> 0.20038435 | F9: ='Income Statement'!F20/'Income Statement'!F6 -> 0.21352734 | G9: ='Income Statement'!G20/'Income Statement'!G6 -> 0.19467803 | H9: ='Income Statement'!H20/'Income Statement'!H6 -> 0.17146201 | I9: ='Income Statement'!I20/'Income Statement'!I6 -> 0.2018018 | ... K9: ='Income Statement'!K20/'Income Statement'!K6 -> 0.18903857
A10: Net Margin = Net Income Avail. to Common / Net Sales | B10: ='Income Statement'!B33/'Income Statement'!B6 -> 0.13035761 | C10: ='Income Statement'!C33/'Income Statement'!C6 -> 0.41958122 | D10: ='Income Statement'!D33/'Income Statement'!D6 -> -0.38800061 | E10: ='Income Statement'!E33/'Income Statement'!E6 -> 0.077471274 | F10: ='Income Statement'!F33/'Income Statement'!F6 -> 0.013596089 | G10: ='Income Statement'!G33/'Income Statement'!G6 -> 0.03885881 | H10: ='Income Statement'!H33/'Income Statement'!H6 -> 0.089223682 | I10: ='Income Statement'!I33/'Income Statement'!I6 -> 0.10716967 | ... K10: ='Income Statement'!K33/'Income Statement'!K6 -> -0.23438377
A11: Return on Equity (ROE) = Net Income Avail. to Common / Total Shareholders’ Equity | B11: ='Income Statement'!B33/'Balance Sheet'!B48 -> 0.060183409 | C11: ='Income Statement'!C33/'Balance Sheet'!C48 -> 0.16611755 | D11: ='Income Statement'!D33/'Balance Sheet'!D48 -> -0.19730143 | E11: ='Income Statement'!E33/'Balance Sheet'!E48 -> 0.037483292 | F11: ='Income Statement'!F33/'Balance Sheet'!F48 -> 0.007105363 | G11: ='Income Statement'!G33/'Balance Sheet'!G48 -> 0.020528216 | H11: ='Income Statement'!H33/'Balance Sheet'!H48 -> 0.04854349 | I11: ='Income Statement'!I33/'Balance Sheet'!I48 -> 0.057646489 | ... K11: ='Income Statement'!K33/'Balance Sheet'!K48 -> -0.14031298
A12: Return on Assets (ROA) = Net Income Avail. to Common / Total Assets | B12: ='Income Statement'!B33/'Balance Sheet'!B26 -> 0.028652058 | C12: ='Income Statement'!C33/'Balance Sheet'!C26 -> 0.091105153 | D12: ='Income Statement'!D33/'Balance Sheet'!D26 -> -0.09851055 | E12: ='Income Statement'!E33/'Balance Sheet'!E26 -> 0.019073435 | F12: ='Income Statement'!F33/'Balance Sheet'!F26 -> 0.0035660623 | G12: ='Income Statement'!G33/'Balance Sheet'!G26 -> 0.010835814 | H12: ='Income Statement'!H33/'Balance Sheet'!H26 -> 0.026106747 | I12: ='Income Statement'!I33/'Balance Sheet'!I26 -> 0.031603184 | ... K12: ='Income Statement'!K33/'Balance Sheet'!K26 -> -0.071479226
A14: 2. PRODUCTIVITY (linked from Balance Sheet tab)
A16: AR Turnover = Net Sales / Accounts Receivable | B16: ='Balance Sheet'!B9 -> 29.488864 | C16: ='Balance Sheet'!C9 -> 20.467818 | D16: ='Balance Sheet'!D9 -> 12.338187 | E16: ='Balance Sheet'!E9 -> 12.659402 | F16: ='Balance Sheet'!F9 -> 12.692196 | G16: ='Balance Sheet'!G9 -> 13.307614 | H16: ='Balance Sheet'!H9 -> 12.492453 | I16: ='Balance Sheet'!I9 -> 12.613636 | ... K16: ='Balance Sheet'!K9 -> 11.065661
A17: Inventory Turnover = COGS incl. D&A / Inventory | B17: ='Balance Sheet'!B11 -> 6.0506706 | C17: ='Balance Sheet'!C11 -> 5.9782609 | D17: ='Balance Sheet'!D11 -> 6.4135733 | E17: ='Balance Sheet'!E11 -> 6.1918412 | F17: ='Balance Sheet'!F11 -> 6.6476116 | G17: ='Balance Sheet'!G11 -> 6.3964822 | H17: ='Balance Sheet'!H11 -> 5.0432758 | I17: ='Balance Sheet'!I11 -> 4.8630327 | ... K17: ='Balance Sheet'!K11 -> 5.2311336
A18: AP Turnover = COGS incl. D&A / Accounts Payable | B18: ='Balance Sheet'!B30 -> 4.0640641 | C18: ='Balance Sheet'!C30 -> 3.7826685 | D18: ='Balance Sheet'!D30 -> 4.1187094 | E18: ='Balance Sheet'!E30 -> 4.2088434 | F18: ='Balance Sheet'!F30 -> 3.9447026 | G18: ='Balance Sheet'!G30 -> 3.6726278 | H18: ='Balance Sheet'!H30 -> 3.7980611 | I18: ='Balance Sheet'!I30 -> 3.7983575 | ... K18: ='Balance Sheet'!K30 -> 3.845636
A19: Total Asset Turnover = Net Sales / Total Assets | B19: ='Income Statement'!B6/'Balance Sheet'!B26 -> 0.21979582 | C19: ='Income Statement'!C6/'Balance Sheet'!C26 -> 0.21713353 | D19: ='Income Statement'!D6/'Balance Sheet'!D26 -> 0.25389277 | E19: ='Income Statement'!E6/'Balance Sheet'!E26 -> 0.2462001 | F19: ='Income Statement'!F6/'Balance Sheet'!F26 -> 0.26228589 | G19: ='Income Statement'!G6/'Balance Sheet'!G26 -> 0.27885089 | H19: ='Income Statement'!H6/'Balance Sheet'!H26 -> 0.29259885 | I19: ='Income Statement'!I6/'Balance Sheet'!I26 -> 0.29488925 | ... K19: ='Income Statement'!K6/'Balance Sheet'!K26 -> 0.30496662
A21: 3. CREDIT RISK
A23: Current Ratio = Total Current Assets / Total Current Liabilities | B23: ='Balance Sheet'!B14/'Balance Sheet'!B34 -> 0.92127145 | C23: ='Balance Sheet'!C14/'Balance Sheet'!C34 -> 0.70917865 | D23: ='Balance Sheet'!D14/'Balance Sheet'!D34 -> 1.2095162 | E23: ='Balance Sheet'!E14/'Balance Sheet'!E34 -> 1.0281905 | F23: ='Balance Sheet'!F14/'Balance Sheet'!F34 -> 1.3425133 | G23: ='Balance Sheet'!G14/'Balance Sheet'!G34 -> 0.99227714 | H23: ='Balance Sheet'!H14/'Balance Sheet'!H34 -> 0.87472308 | I23: ='Balance Sheet'!I14/'Balance Sheet'!I34 -> 0.98656215 | ... K23: ='Balance Sheet'!K14/'Balance Sheet'!K34 -> 1.1536797
A24: Debt-to-Equity = (ST Debt + LT Debt) / Total Shareholders’ Equity | B24: =('Balance Sheet'!B31+'Balance Sheet'!B36)/'Balance Sheet'!B48 -> 0.56494299 | C24: =('Balance Sheet'!C31+'Balance Sheet'!C36)/'Balance Sheet'!C48 -> 0.47831104 | D24: =('Balance Sheet'!D31+'Balance Sheet'!D36)/'Balance Sheet'!D48 -> 0.6033645 | E24: =('Balance Sheet'!E31+'Balance Sheet'!E36)/'Balance Sheet'!E48 -> 0.57813378 | F24: =('Balance Sheet'!F31+'Balance Sheet'!F36)/'Balance Sheet'!F48 -> 0.57713111 | G24: =('Balance Sheet'!G31+'Balance Sheet'!G36)/'Balance Sheet'!G48 -> 0.4550286 | H24: =('Balance Sheet'!H31+'Balance Sheet'!H36)/'Balance Sheet'!H48 -> 0.42688689 | I24: =('Balance Sheet'!I31+'Balance Sheet'!I36)/'Balance Sheet'!I48 -> 0.41693252 | ... K24: =('Balance Sheet'!K31+'Balance Sheet'!K36)/'Balance Sheet'!K48 -> 0.52256144
A25: Interest Coverage = EBIT / Interest Expense | B25: ='Income Statement'!B20/'Income Statement'!B24 -> 6.2814159 | C25: ='Income Statement'!C20/'Income Statement'!C24 -> 5.3407351 | D25: ='Income Statement'!D20/'Income Statement'!D24 -> 4.5837246 | E25: ='Income Statement'!E20/'Income Statement'!E24 -> 3.6111111 | F25: ='Income Statement'!F20/'Income Statement'!F24 -> 3.9821937 | G25: ='Income Statement'!G20/'Income Statement'!G24 -> 2.4587779 | H25: ='Income Statement'!H20/'Income Statement'!H24 -> 4.893319 | I25: ='Income Statement'!I20/'Income Statement'!I24 -> 5.8434783 | ... K25: ='Income Statement'!K20/'Income Statement'!K24 -> 4.8408624
A27: Altman Z”-Score = 6.56(X1) + 3.26(X2) + 6.72(X3) + 1.05(X4)
A28: X1 = Working Capital / Total Assets | I28: =('Balance Sheet'!I14-'Balance Sheet'!I34)/'Balance Sheet'!I26 -> -0.001195497 | J28: =('Balance Sheet'!J14-'Balance Sheet'!J34)/'Balance Sheet'!J26 -> 0.0045533317 | K28: =('Balance Sheet'!K14-'Balance Sheet'!K34)/'Balance Sheet'!K26 -> 0.016494266
A29: X2 = Retained Earnings / Total Assets | I29: ='Balance Sheet'!I44/'Balance Sheet'!I26 -> 0.015131892 | J29: ='Balance Sheet'!J44/'Balance Sheet'!J26 -> 0.024590257 | K29: ='Balance Sheet'!K44/'Balance Sheet'!K26 -> -0.056598929
A30: X3 = EBIT / Total Assets | I30: ='Income Statement'!I20/'Balance Sheet'!I26 -> 0.059509182 | J30: ='Income Statement'!J20/'Balance Sheet'!J26 -> 0.061073544 | K30: ='Income Statement'!K20/'Balance Sheet'!K26 -> 0.057650454
A31: X4 = Book Value of Total Shareholders’ Equity / Total Liabilities | I31: ='Balance Sheet'!I48/'Balance Sheet'!I39 -> 1.2193417 | J31: ='Balance Sheet'!J48/'Balance Sheet'!J39 -> 1.2623839 | K31: ='Balance Sheet'!K48/'Balance Sheet'!K39 -> 1.0416781
A32: Altman Z”-Score | I32: =6.56*I28+3.26*I29+6.72*I30+1.05*I31 -> 1.7216979 | J32: =6.56*J28+3.26*J29+6.72*J30+1.05*J31 -> 1.8459514 | K32: =6.56*K28+3.26*K29+6.72*K30+1.05*K31 -> 1.404863
A33: Zone | I33: =IF(I32>2.6,"Safe",IF(I32>1.1,"Grey Zone","Distress Zone")) -> Grey Zone | J33: =IF(J32>2.6,"Safe",IF(J32>1.1,"Grey Zone","Distress Zone")) -> Grey Zone | K33: =IF(K32>2.6,"Safe",IF(K32>1.1,"Grey Zone","Distress Zone")) -> Grey Zone
A34: Note: Altman Z” (private-firm / non-manufacturer variant, book value of equity, no asset-turnover term) computed for FY2023-FY2025 to match the trend period discussed in Point 7A. Zones: Distress < 1.1, Grey Zone 1.1-2.6, Safe > 2.6.

Sheet Growth
A1: Kraft Heinz Company (KHC) — Historical & Forecasted Growth (Point 4)
A2: Comparable: McCormick & Company (MKC) | Black = same-sheet formula, Green = link to other sheet, Blue = input assumption (external source)
A4: 1. KHC — HISTORICAL GROWTH (FY2016-FY2025)
A6: Fiscal Year | B6: ='Income Statement'!B4 -> 2016 | C6: ='Income Statement'!C4 -> 2017 | D6: ='Income Statement'!D4 -> 2018 | E6: ='Income Statement'!E4 -> 2019 | F6: ='Income Statement'!F4 -> 2020 | G6: ='Income Statement'!G4 -> 2021 | H6: ='Income Statement'!H4 -> 2022 | I6: ='Income Statement'!I4 -> 2023 | ... K6: ='Income Statement'!K4 -> 2025
A8: Net Sales ($mm) | B8: ='Income Statement'!B6 -> 26481 | C8: ='Income Statement'!C6 -> 26076 | D8: ='Income Statement'!D6 -> 26268 | E8: ='Income Statement'!E6 -> 24977 | F8: ='Income Statement'!F6 -> 26184 | G8: ='Income Statement'!G6 -> 26043 | H8: ='Income Statement'!H6 -> 26484 | I8: ='Income Statement'!I6 -> 26640 | ... K8: ='Income Statement'!K6 -> 24942
A9: EBITDA ($mm) = EBIT + Depreciation + Amortization | B9: ='Income Statement'!B20+'Income Statement'!B11+'Income Statement'!B13 -> 8435 | C9: ='Income Statement'!C20+'Income Statement'!C11+'Income Statement'!C13 -> 8006 | D9: ='Income Statement'!D20+'Income Statement'!D11+'Income Statement'!D13 -> 6841 | E9: ='Income Statement'!E20+'Income Statement'!E11+'Income Statement'!E13 -> 5999 | F9: ='Income Statement'!F20+'Income Statement'!F11+'Income Statement'!F13 -> 6560 | G9: ='Income Statement'!G20+'Income Statement'!G11+'Income Statement'!G13 -> 5980 | H9: ='Income Statement'!H20+'Income Statement'!H11+'Income Statement'!H13 -> 5474 | I9: ='Income Statement'!I20+'Income Statement'!I11+'Income Statement'!I13 -> 6337 | ... K9: ='Income Statement'!K20+'Income Statement'!K11+'Income Statement'!K13 -> 5683
A10: EPS, Basic ($) | B10: ='Income Statement'!B55 -> 2.8364832 | C10: ='Income Statement'!C55 -> 8.9827586 | D10: ='Income Statement'!D55 -> -8.3609516 | E10: ='Income Statement'!E55 -> 1.5847666 | F10: ='Income Statement'!F55 -> 0.29108749 | G10: ='Income Statement'!G55 -> 0.82679739 | H10: ='Income Statement'!H55 -> 1.9274062 | I10: ='Income Statement'!I55 -> 2.3268134 | ... K10: ='Income Statement'!K55 -> -4.9250211
A12: 10-Year CAGR, FY2016-FY2025
A13: Net Sales CAGR | C13: =(K8/B8)^(1/9)-1 -> -0.006630627
A14: EBITDA CAGR | C14: =(K9/B9)^(1/9)-1 -> -0.042930186
A15: EPS CAGR — not meaningful (see note) | C15: "n/m"
A16: Note: EPS CAGR cannot be meaningfully calculated over FY2016-FY2025 because EPS changes sign multiple times (FY2017 one-time tax-reform benefit of $8.98; FY2018 impairment-driven loss of ($8.36); FY2025 goodwill-impairment loss of ($4.93)) — a compound growth rate is undefined/misleading across sign reversals. The raw EPS series above is presented instead; the takeaway is extreme period-to-period volatility driven by non-cash impairments, not an underlying earnings trend.
A18: 2. KHC — FORECASTED GROWTH (FY2026-FY2030)
A20: Fiscal Year | B20: ='Income Statement'!M4 -> 2026 | C20: ='Income Statement'!N4 -> 2027 | D20: ='Income Statement'!O4 -> 2028 | E20: ='Income Statement'!P4 -> 2029 | F20: ='Income Statement'!Q4 -> 2030
A22: Net Sales ($mm) | B22: ='Income Statement'!M6 -> 24786.539 | C22: ='Income Statement'!N6 -> 24632.048 | D22: ='Income Statement'!O6 -> 24478.519 | E22: ='Income Statement'!P6 -> 24325.947 | F22: ='Income Statement'!Q6 -> 24174.326
A23: EBITDA ($mm) | B23: ='Income Statement'!M20+'Income Statement'!M11+'Income Statement'!M13 -> 6256.2133 | C23: ='Income Statement'!N20+'Income Statement'!N11+'Income Statement'!N13 -> 6217.219 | D23: ='Income Statement'!O20+'Income Statement'!O11+'Income Statement'!O13 -> 6178.4678 | E23: ='Income Statement'!P20+'Income Statement'!P11+'Income Statement'!P13 -> 6139.9581 | F23: ='Income Statement'!Q20+'Income Statement'!Q11+'Income Statement'!Q13 -> 6101.6885
A24: EPS, Basic ($) | B24: ='Income Statement'!M55 -> 2.8643873 | C24: ='Income Statement'!N55 -> 2.8313353 | D24: ='Income Statement'!O55 -> 2.7996321 | E24: ='Income Statement'!P55 -> 2.7691596 | F24: ='Income Statement'!Q55 -> 2.7398107
A26: 4-Year Forecast CAGR, FY2026-FY2030
A27: Net Sales CAGR | C27: =(F22/B22)^(1/4)-1 -> -0.006232886
A28: EBITDA CAGR | C28: =(F23/B23)^(1/4)-1 -> -0.006232886
A29: EPS CAGR | C29: =(F24/B24)^(1/4)-1 -> -0.011054851
A30: Note: All forecast years exclude non-recurring impairments (Income Statement, row 51), so forecast EPS is consistently positive and a CAGR is meaningful, unlike the historical series above.
A32: 3. COMPARABLE — MCCORMICK & COMPANY (MKC) HISTORICAL & FORECASTED GROWTH
A33: Source: FIN4035_2026Summer_MKC_Week12.xlsx, "Growth" tab (course-provided, week 12), accessed 8/2/2026. Hardcoded per source — not derived from KHC model.
A35: Measure | B35: Value | C35: Sample Period | D35: Estimation Method
A36: Historical Sales Growth | B36: 0.02020388 | C36: 2022-2025 | D36: Arithmetic Average
A37: Historical EPS Growth | B37: 0.012190361 | C37: 2020-2025 | D37: Geometric Average
A38: Forecast Sales Growth (Analyst Consensus) | B38: 0.035479321 | C38: 2027-2028 | D38: Arithmetic Average
A39: Forecast EPS Growth — Short Run | B39: 0.048980583 | C39: 2026-2027 | D39: Arithmetic Average
A40: Forecast EPS Growth — Long Run | B40: 0.07 | C40: n/a | D40: Analyst Long-Term Estimate
A41: Forecast EBITDA Growth | B41: 0.060661765 | C41: n/a | D41: Arithmetic Average
A43: 4. SUMMARY — KHC vs. MKC GROWTH COMPARISON
A45: Measure | B45: KHC | C45: MKC
A46: Historical Sales Growth (CAGR) | B46: =C13 -> -0.006630627 | C46: =B36 -> 0.02020388
A47: Historical EPS Growth | B47: ="n/m (sign reversals)" -> n/m (sign reversals) | C47: =B37 -> 0.012190361
A48: Forecast Sales Growth | B48: =C27 -> -0.006232886 | C48: =B38 -> 0.035479321
A49: Forecast EPS Growth | B49: =C29 -> -0.011054851 | C49: =B39 -> 0.048980583
A50: Forecast EBITDA Growth | B50: =C28 -> -0.006232886 | C50: =B41 -> 0.060661765
A52: Takeaway: KHC’s forecast growth is modestly negative across Sales/EBITDA/EPS (conservative, historical-trend-driven baseline), while MKC is forecast to grow low-to-mid single digits across all three measures — consistent with MKC’s stronger historical trend and analyst outlook. This growth gap is a key driver of the differing valuation multiples applied in Point 5.

Sheet Relative Valuation
A1: Kraft Heinz Company (KHC) — Relative Valuation (Point 5)
A2: $ in millions except per-share and multiple values | Comparable: McCormick & Co. (MKC) | Black = same-sheet formula, Green = link to other sheet, Blue = input assumption (external source)
A4: 1. DATA SOURCE & PRICE CORRECTION NOTE
A6: Source: FIN4035_2026Summer_Comp.xlsx, "Relative Valuation Input" tab (course-provided), figures as of 7/27/2026, accessed 8/2/2026.
A7: CORRECTION: the source file's per-share price row (row 16) lists KHC at $50.61 and MKC at $26.22. Live market data checked 8/2/2026 (StockAnalysis.com, TradingView) shows KHC trading ~$25-28/share and MKC trading ~$48-64/share — all other fields (net income, shares outstanding, EBIT, D&A) check out against public data for both companies, isolating the error to this one row. The KHC and MKC prices appear transposed in the source file. Prices below are corrected accordingly and flagged for the professor.
A9: 2. INPUT DATA (FY2025 / TTM, as of 7/27/2026 unless noted)
A11: Measure | B11: KHC | C11: MKC
A12: Current Price per Share (corrected) | B12: 25.37 | C12: 50.61
A13: Diluted Shares Outstanding (mm) | B13: ='Income Statement'!$K$35 -> 1187 | C13: 269.4
A14: Net Income — Adjusted (excl. non-recurring items) | B14: -5813.2838 | C14: 802.61324
A15: EPS — Adjusted, Diluted | B15: =B14/B13 -> -4.897459 | C15: =C14/C13 -> 2.9792622
A16: EBIT — Adjusted | B16: 4745.4617 | C16: 1109.3205
A17: D&A — Adjusted | B17: 1104.6 | C17: 319.54
A18: EBITDA — Adjusted = EBIT + D&A | B18: =B16+B17 -> 5850.0617 | C18: =C16+C17 -> 1428.8605
A19: Total Debt | B19: ='Cost of Capital (WACC)'!$B$59 -> 21772 | C19: 4222.9
A20: Cash & Short-Term Investments | B20: ='Balance Sheet'!$K$7 -> 3839 | C20: 95.9
A21: Market Value of Equity = Price x Shares | B21: =B12*B13 -> 30114.19 | C21: =C12*C13 -> 13634.334
A22: Enterprise Value = MVE + Debt - Cash | B22: =B21+B19-B20 -> 48047.19 | C22: =C21+C19-C20 -> 17761.334
A23: FY2026E Net Income Available to Common (forward, from own model) | B23: ='Income Statement'!$M$33 -> 3400.0277
A24: FY2026E EPS (forward) | B24: =B23/B13 -> 2.8643873
A26: 3. VALUATION MULTIPLES — MKC (COMPARABLE)
A28: P/E (MKC, adjusted EPS) | C28: =C12/C15 -> 16.987427
A29: EV/EBITDA (MKC, adjusted) | C29: =C22/C18 -> 12.430418
A30: Note: KHC’s own P/E is not meaningful — both unadjusted and adjusted net income remain negative in FY2025 (the goodwill impairment is not backed out of the "adjusted" figure in the source data), so a P/E-based implied price cannot be computed off trailing KHC earnings. EV/EBITDA is used as the primary multiple, consistent with Point 5’s qualitative discussion. A secondary, forward-looking P/E check uses KHC’s own FY2026E forecast EPS (positive, since the forecast excludes non-recurring impairments) against MKC’s trailing P/E — an imperfect but directionally useful cross-check.
A32: 4. IMPLIED KHC VALUE — MULTIPLES APPLIED
A34: Model | B34: Multiple | C34: KHC Metric | D34: Implied Value | E34: Implied Share Price
A35: EV/EBITDA (MKC multiple x KHC Adj. EBITDA) | B35: =C29 -> 12.430418 | C35: =B18 -> 5850.0617 | D35: =B35*C35 -> 72718.713 | E35: =(D35-B19+B20)/B13 -> 46.154771
A36: P/E, Trailing (MKC multiple x KHC Adj. EPS) — n/m, KHC EPS negative | B36: =C28 -> 16.987427 | C36: =B15 -> -4.897459 | D36: ="n/m" -> n/m | E36: ="n/m" -> n/m
A37: P/E, Forward (MKC trailing multiple x KHC FY2026E EPS) — secondary check | B37: =C28 -> 16.987427 | C37: =B24 -> 2.8643873 | D37: =B37*C37 -> 48.658571 | E37: =D37 -> 48.658571
A39: Current KHC Market Price | C39: 25.37
A40: Implied Upside/(Downside) — EV/EBITDA Model | C40: =E35/C39-1 -> 0.81926569
A41: Implied Upside/(Downside) — Forward P/E Model | C41: =E37/C39-1 -> 0.91795707
A43: Takeaway: KHC trades at a discount to MKC on both an EV/EBITDA basis (applying MKC’s multiple to KHC’s own EBITDA implies meaningful upside from the current $25.37) and a forward P/E basis. This is directionally consistent with the FCFF/FCFE DCF results (Point 8), though the gap partly reflects MKC’s stronger growth outlook (Point 4) and higher quality/rating perception — not purely mispricing. See write-up for full discussion of drivers.

Sheet Cash Flow Statement
A1: Kraft Heinz Company (KHC) — Cash Flow Statement
A2: $ in millions | Rows 7-37: historical actual (as reported) | Rows 40-69: forecast, built indirectly from the forecasted Income Statement & Balance Sheet
B4: Historical | M4: Forecast
B5: 2016 | C5: 2017 | D5: 2018 | E5: 2019 | F5: 2020 | G5: 2021 | H5: 2022 | I5: 2023 | J5: 2024 | K5: 2025 | M5: 2026 | N5: 2027 | O5: 2028 | P5: 2029 | Q5: 2030
A7: HISTORICAL CASH FLOW STATEMENT (as reported)
A8: OPERATING ACTIVITIES
A9: Net Income (Consolidated) | B9: 3642 | C9: 10932 | D9: -10254 | E9: 1933 | F9: 361 | G9: 1024 | H9: 2368 | I9: 2846 | J9: 2746 | K9: -5848
A10: Add: Depreciation & Amortization | B10: 1337 | C10: 1031 | D10: 983 | E10: 994 | F10: 969 | G10: 910 | H10: 933 | I10: 961 | J10: 948 | K10: 968
A11: Add/(Less): Deferred Taxes | B11: -29 | C11: -6495 | D11: -1967 | E11: -293 | F11: -343 | G11: -1042 | H11: -278 | I11: 17 | J11: -2857 | K11: -495
A12: Add: Other Non-Cash Items (incl. impairments) | B12: -741 | C12: -1603 | D12: 15875 | E12: 1151 | F12: 3495 | G12: 4066 | H12: 929 | I12: 958 | J12: 3936 | K12: 9607
A13: Change in Accounts Receivable | B13: 534 | C13: -2629 | D13: -2280 | E13: 140 | F13: -26 | G13: 87 | H13: -228 | I13: 18 | J13: -139 | K13: -55
A14: Change in Inventories | B14: -130 | C14: -236 | D14: -251 | E14: -277 | F14: -266 | G14: -144 | H14: -1121 | I14: -106 | J14: -6 | K14: 133
A15: Change in Accounts Payable | B15: 943 | C15: 441 | D15: -23 | E15: -58 | F15: 207 | G15: 408 | H15: 152 | I15: -295 | J15: -308 | K15: -97
A16: Change in Other Assets/Liabilities | B16: -318 | C16: -940 | D16: 491 | E16: -38 | F16: 532 | G16: 55 | H16: -286 | I16: -423 | J16: -136 | K16: 249
A17: Net Cash from Operating Activities | B17: =SUM(B9:B16) -> 5238 | C17: =SUM(C9:C16) -> 501 | D17: =SUM(D9:D16) -> 2574 | E17: =SUM(E9:E16) -> 3552 | F17: =SUM(F9:F16) -> 4929 | G17: =SUM(G9:G16) -> 5364 | H17: =SUM(H9:H16) -> 2469 | I17: =SUM(I9:I16) -> 3976 | ... K17: =SUM(K9:K16) -> 4462
A19: INVESTING ACTIVITIES
A20: Capital Expenditures | B20: -1247 | C20: -1194 | D20: -826 | E20: -768 | F20: -596 | G20: -905 | H20: -916 | I20: -1013 | J20: -1164 | K20: -801
A21: Other Investing Activities, net (acquisitions/disposals/investments) | B21: =B22-B20 -> 134 | C21: =C22-C20 -> 2371 | D21: =D22-D20 -> 1114 | E21: =E22-E20 -> 2279 | F21: =F22-F20 -> 74 | G21: =G22-G20 -> 4943 | H21: =H22-H20 -> -175 | I21: =I22-I20 -> 97 | ... K21: =K22-K20 -> -1032
A22: Net Cash from Investing Activities | B22: -1113 | C22: 1177 | D22: 288 | E22: 1511 | F22: -522 | G22: 4038 | H22: -1091 | I22: -916 | J22: -1023 | K22: -1833
A24: FINANCING ACTIVITIES
A25: Common & Preferred Dividends Paid | B25: -3764 | C25: -2888 | D25: -3183 | E25: -1953 | F25: -1958 | G25: -1959 | H25: -1960 | I25: -1965 | J25: -1931 | K25: -1898
A26: Debt Issuance/(Repayment), Net | B26: 7479 | C26: -1351 | D26: -152 | E26: -1927 | F26: -1313 | G26: -7126 | H26: -1455 | I26: -191 | J26: -24 | K26: 942
A27: Repurchase of Common Stock, Net | B27: -8320 | C27: 0 | D27: 0 | E27: 0 | F27: 0 | G27: 0 | H27: 0 | I27: -455 | J27: -988 | K27: -436
A28: Other Financing Activities, net | B28: -16 | C28: 18 | D28: -28 | E28: -33 | F28: -60 | G28: -259 | H28: -299 | I28: -67 | J28: -65 | K28: 141
A29: Net Cash from Financing Activities | B29: =SUM(B25:B28) -> -4621 | C29: =SUM(C25:C28) -> -4221 | D29: =SUM(D25:D28) -> -3363 | E29: =SUM(E25:E28) -> -3913 | F29: =SUM(F25:F28) -> -3331 | G29: =SUM(G25:G28) -> -9344 | H29: =SUM(H25:H28) -> -3714 | I29: =SUM(I25:I28) -> -2678 | ... K29: =SUM(K25:K28) -> -1251
A31: Foreign Exchange Effect on Cash | B31: -137 | C31: 57 | D31: -132 | E31: -6 | F31: 62 | G31: -30 | H31: -69 | I31: -19 | J31: -71 | K31: 80
A32: NET CHANGE IN CASH (as reported) | B32: =B17+B22+B29+B31 -> -633 | C32: =C17+C22+C29+C31 -> -2486 | D32: =D17+D22+D29+D31 -> -633 | E32: =E17+E22+E29+E31 -> 1144 | F32: =F17+F22+F29+F31 -> 1138 | G32: =G17+G22+G29+G31 -> 28 | H32: =H17+H22+H29+H31 -> -2405 | I32: =I17+I22+I29+I31 -> 363 | ... K32: =K17+K22+K29+K31 -> 1458
A34: Memo: Cash & STI, Beginning of Year (Balance Sheet) | C34: ='Balance Sheet'!B7 -> 4204 | D34: ='Balance Sheet'!C7 -> 1769 | E34: ='Balance Sheet'!D7 -> 1131 | F34: ='Balance Sheet'!E7 -> 2280 | G34: ='Balance Sheet'!F7 -> 3417 | H34: ='Balance Sheet'!G7 -> 3445 | I34: ='Balance Sheet'!H7 -> 1040 | J34: ='Balance Sheet'!I7 -> 1403 | K34: ='Balance Sheet'!J7 -> 1365
A35: Memo: Cash & STI, End of Year (Balance Sheet) | B35: ='Balance Sheet'!B7 -> 4204 | C35: ='Balance Sheet'!C7 -> 1769 | D35: ='Balance Sheet'!D7 -> 1131 | E35: ='Balance Sheet'!E7 -> 2280 | F35: ='Balance Sheet'!F7 -> 3417 | G35: ='Balance Sheet'!G7 -> 3445 | H35: ='Balance Sheet'!H7 -> 1040 | I35: ='Balance Sheet'!I7 -> 1403 | ... K35: ='Balance Sheet'!K7 -> 3839
A36: Memo: Implied Change per Balance Sheet | C36: =C35-C34 -> -2435 | D36: =D35-D34 -> -638 | E36: =E35-E34 -> 1149 | F36: =F35-F34 -> 1137 | G36: =G35-G34 -> 28 | H36: =H35-H34 -> -2405 | I36: =I35-I34 -> 363 | J36: =J35-J34 -> -38 | K36: =K35-K34 -> 2474
A37: Memo: Reported vs. BS-Implied Change, Difference | C37: =C32-C36 -> -51 | D37: =D32-D36 -> 5 | E37: =E32-E36 -> -5 | F37: =F32-F36 -> 1 | G37: =G32-G36 -> 0 | H37: =H32-H36 -> 0 | I37: =I32-I36 -> 0 | J37: =J32-J36 -> 120 | K37: =K32-K36 -> -1016
A38: Note: Small differences between the reported Net Change in Cash and the Balance Sheet-implied change are expected — the CF statement's cash definition can differ slightly from Cash & Short-Term Investments (e.g., restricted cash, FX timing). This does not affect the forecast, which is self-consistent by construction below.
A40: FORECAST CASH FLOW STATEMENT (Indirect Method, per Topic 7)
A41: OPERATING ACTIVITIES
A42: Net Income Available to Common | M42: ='Income Statement'!M33 -> 3400.0277 | N42: ='Income Statement'!N33 -> 3360.795 | O42: ='Income Statement'!O33 -> 3323.1633 | P42: ='Income Statement'!P33 -> 3286.9924 | Q42: ='Income Statement'!Q33 -> 3252.1553
A43: Add: Depreciation Expense | M43: ='Income Statement'!M11 -> 753.36108 | N43: ='Income Statement'!N11 -> 767.2763 | O43: ='Income Statement'!O11 -> 779.31599 | P43: ='Income Statement'!P11 -> 789.66375 | Q43: ='Income Statement'!Q11 -> 798.48556
A44: Add: Amortization Expense | M44: ='Income Statement'!M13 -> 207.86039 | N44: ='Income Statement'!N13 -> 206.70912 | O44: ='Income Statement'!O13 -> 205.56423 | P44: ='Income Statement'!P13 -> 204.42568 | Q44: ='Income Statement'!Q13 -> 203.29343
A45: Less: Increase in Accounts Receivable | M45: =-('Balance Sheet'!M8-'Balance Sheet'!K8) -> 592.30311 | N45: =-('Balance Sheet'!N8-'Balance Sheet'!M8) -> 10.357167 | O45: =-('Balance Sheet'!O8-'Balance Sheet'!N8) -> 10.292612 | P45: =-('Balance Sheet'!P8-'Balance Sheet'!O8) -> 10.22846 | Q45: =-('Balance Sheet'!Q8-'Balance Sheet'!P8) -> 10.164707
A46: Less: Increase in Inventories | M46: =-('Balance Sheet'!M10-'Balance Sheet'!K10) -> 352.73206 | N46: =-('Balance Sheet'!N10-'Balance Sheet'!M10) -> 14.296687 | O46: =-('Balance Sheet'!O10-'Balance Sheet'!N10) -> 14.517149 | P46: =-('Balance Sheet'!P10-'Balance Sheet'!O10) -> 14.706495 | Q46: =-('Balance Sheet'!Q10-'Balance Sheet'!P10) -> 14.867777
A47: Add: Increase in Accounts Payable | M47: =('Balance Sheet'!M29-'Balance Sheet'!K29) -> -163.94947 | N47: =('Balance Sheet'!N29-'Balance Sheet'!M29) -> -21.052079 | O47: =('Balance Sheet'!O29-'Balance Sheet'!N29) -> -21.376714 | P47: =('Balance Sheet'!P29-'Balance Sheet'!O29) -> -21.655528 | Q47: =('Balance Sheet'!Q29-'Balance Sheet'!P29) -> -21.893018
...

Sheet Cost of Capital (WACC)
A1: Kraft Heinz Company (KHC) — Cost of Capital Analysis
A2: $ in millions unless noted | Blue = hardcoded input/source data, Black = formula, Green = link to other sheet | Prepared for FIN4035 — Financial Markets Analysis
A3: All market data as of July 24-25, 2026 (see Sources tab for full citations)
A5: 1. COST OF EQUITY
A7: 1a. Risk-Free Rate
A8: Current 10-Year U.S. Treasury Yield (10Y UST) | B8: 0.0468 | G8: Source: FRED (DGS10) / Trading Economics, 10Y UST close, 7/24/2026
A10: 1b. Equity Market Risk Premium (MRP)
A11: Historical MRP — Arithmetic avg., Stocks minus T.Bonds, 1928-2025 | B11: 0.066 | G11: Source: Damodaran, 'Data Update 2 for 2026' & NYU Stern historical returns dataset (histretSP.xls). Verify exact decimal against the current-year download — figure is approximate/rounded from the 1928-2025 series.
A12: Implied MRP (forward-looking, model-agnostic, as of 1/1/2026) | B12: 0.0423 | G12: Source: Damodaran, 'Data Update 2 for 2026: A Testing Year (2025) for US Equities' (Jan 2026); implied ERP computed from S&P 500 index level 6,845.5 on 1/1/2026, less 10Y UST bond rate.
A14: 1c. Beta
A15: Historical Regression Beta (5-Year Monthly, vs. S&P 500) | B15: 0.08 | G15: Source: Yahoo Finance, KHC key statistics, Beta (5Y Monthly), accessed 7/25/2026. Unusually low — reflects KHC's defensive/low-volatility trading pattern and idiosyncratic events (spin-off news, impairments) decoupling the stock from broad market moves.
A17: Bottom-Up Beta Build
A18: Unlevered Beta — Food Processing industry (US, 78 firms) | B18: 0.46 | G18: Source: Damodaran, 'Betas by Sector (US)', data as of January 2026 (pages.stern.nyu.edu/~adamodar/New_Home_Page/datafile/Betas.html) — Food Processing industry row.
A19: KHC Market Value of Equity ($mm) | B19: 30100 | G19: Source: Share price $25.37 x ~1,186mm diluted shares outstanding (Yahoo Finance / StockAnalysis.com, 7/23/2026).
A20: KHC Total Debt ($mm) — book value used as proxy for market value | B20: 21100 | G20: Source: StockAnalysis.com KHC statistics ($21.13B total debt, data as of 7/2/2026); consistent with FY2025 ST+LT debt of $21,772mm on the Balance Sheet tab.
A21: KHC Debt-to-Equity Ratio (D/E) | B21: =B20/B19 -> 0.70099668
A22: Marginal Tax Rate (blended federal + state, assumption) | B22: 0.25 | G22: Assumption: 21% U.S. federal statutory rate plus ~4% blended state effective rate — standard assumption for a large multinational U.S. corporate issuer.
A23: Bottom-Up (Relevered) Beta = Unlevered Beta x [1 + (1-t) x D/E] | B23: =B18*(1+(1-B22)*B21) -> 0.70184385
A25: 1d. Revenue-Weighted Country Risk Premium (CRP)
A26: Region | B26: FY2025 Net Sales ($mm) | C26: % of Total Revenue | D26: Country Risk Premium | E26: Weighted CRP
A27: United States | B27: 16780 | C27: =B27/$B$31 -> 0.67281476 | D27: 0.0023 | E27: =C27*D27 -> 0.0015474739 | G27: US — Aa1/AA sovereign rating, developed-market baseline
A28: Canada | B28: 1800 | C28: =B28/$B$31 -> 0.072173216 | D28: 0 | E28: =C28*D28 -> 0 | G28: Canada — Aaa, zero country risk premium
A29: United Kingdom | B29: 1270 | C29: =B29/$B$31 -> 0.050922213 | D29: 0.0078 | E29: =C29*D29 -> 0.00039719326 | G29: UK — Aa3 sovereign rating
A30: Rest of World (Intl. Developed + Emerging Mkts.) | B30: 5090 | C30: =B30/$B$31 -> 0.20408982 | D30: 0.022 | E30: =C30*D30 -> 0.0044899759 | G30: Blended estimate: mix of developed Europe/Pacific (Italy, Netherlands, Australia, NZ) and emerging markets (Brazil, Indonesia, India, etc.) per Damodaran country CRP table — approximation; exact country-level revenue split not separately disclosed in the 10-K.
A31: Total FY2025 Net Sales | B31: =SUM(B27:B30) -> 24940 | C31: =SUM(C27:C30) -> 1 | G31: Source: Bullfincher.io / KHC 10-K Note 21 Segment Reporting, FY2025 net sales by region (US $16.78B, Canada $1.80B, UK $1.27B, Rest of World $5.09B).
A32: Revenue-Weighted Country Risk Premium | B32: =SUM(E27:E30) -> 0.0064346431
A34: 1e. Cost of Equity — CAPM
A35: Ke = Rf + Beta x MRP + Country Risk Premium
B36: Historical MRP | C36: Implied MRP
A37: Ke, using Historical Regression Beta | B37: =$B$8+$B$15*B11+$B$32 -> 0.058514643 | C37: =$B$8+$B$15*$B$12+$B$32 -> 0.056618643
A38: Ke, using Bottom-Up (Relevered) Beta | B38: =$B$8+$B$23*B11+$B$32 -> 0.099556337 | C38: =$B$8+$B$23*$B$12+$B$32 -> 0.082922638 | G38: SELECTED Cost of Equity: Bottom-Up Beta x Implied MRP. The bottom-up beta (from ~78 food-processing peers) is far less noisy than KHC's own low/unstable regression beta (0.08), and the implied ERP is the forward-looking, model-agnostic estimate Damodaran himself recommends over the backward-looking historical average.
A39: SELECTED Cost of Equity (Ke) | B39: =C38 -> 0.082922638
A42: 2. COST OF DEBT
A44: KHC Long-Term Debt Ratings
A45: Current Senior Unsecured Ratings (Moody's / S&P / Fitch) | B45: Baa2 / BBB / BBB | G45: Source: Kraft Heinz Foods Company FWP, SEC filing, May 2026 pricing term sheet (2031/2034 EUR notes); ratings stable across agencies as of mid-2026.
A47: 2a-e. Estimates of KHC's Current Borrowing Cost
A48: Method | B48: Pretax Cost of Debt
A49: (a) Corporate Bond YTM — KHC 3.75% Senior Notes due 4/1/2030 | B49: 0.0444 | G49: Source: Public.com bond screener, KHC 3.75% 4/1/2030 note, market YTM as of 7/2026.
A50: (b) Comparable Bond YTM — McCormick & Co. (Baa2/BBB), average across outstanding notes/bonds | B50: 0.049356338 | G50: Source: McCormick & Co. outstanding notes/bonds, average YTM across issues (course-provided Comp file, FactSet/Bloomberg bond data, accessed 7/27/2026); used as a similarly-rated (Baa2/BBB) food-sector peer.
A51: Baa2/BBB Default Spread (large-cap, non-financial, over 10Y UST) | B51: 0.0111 | G51: Source: Damodaran, 'Ratings, Interest Coverage Ratios and Default Spread' table, data as of January 2026 — Baa2/BBB row (interest coverage 2.50x-2.999x bracket), spread = 1.11%.
...

Sheet DCF Valuation
A1: Kraft Heinz Company (KHC) — Discounted Cash Flow Valuation (Point 8)
A2: $ in millions except per-share values | PV of explicit FY2026-2030 forecast + PV of terminal value, discounted at WACC (FCFF, ROPI) or Cost of Equity (FCFE, RI) | Black = same-sheet formula, Green = link to other sheet, Blue = input assumption
A4: 1. DISCOUNTING ASSUMPTIONS
A6: Forecast Year | B6: ='Cash Flow Statement'!M4 -> Forecast | C6: ='Cash Flow Statement'!N4 -> 0 | D6: ='Cash Flow Statement'!O4 -> 0 | E6: ='Cash Flow Statement'!P4 -> 0 | F6: ='Cash Flow Statement'!Q4 -> 0
A7: Discount Period (t) | B7: 1 | C7: 2 | D7: 3 | E7: 4 | F7: 5
A9: WACC (discount rate — FCFF & ROPI models) | C9: ='Cost of Capital (WACC)'!$B$89 -> 0.066645291
A10: Cost of Equity, Ke (discount rate — FCFE & RI models) | C10: ='Cost of Capital (WACC)'!$B$39 -> 0.082922638
